2025-09-12T23:08:59 {"cpu": 0.2568359375, "cpu_total": 20, "cpu_usage": 0.012841796875, "memory": 2021.0, "memory_total": 9804.0, "memory_usage": 0.20614035087719298, "pipeline_run_id": 8, "pipeline_schedule_id": 3, "pipeline_uuid": "qb_items_backfill", "hostname": "370646b43903", "level": "INFO", "message": "Pipeline qb_items_backfill for run 8 in schedule 3 is alive.", "timestamp": 1757718539.752935, "uuid": "ac0863e9a4ae497a93f0284aff9bcbea"}
2025-09-12T23:09:00 {"cpu": 0.2568359375, "cpu_total": 20, "cpu_usage": 0.012841796875, "memory": 2054.0, "memory_total": 9804.0, "memory_usage": 0.2095063239494084, "pipeline_run_id": 8, "pipeline_schedule_id": 3, "pipeline_uuid": "qb_items_backfill", "hostname": "370646b43903", "level": "INFO", "message": "Pipeline qb_items_backfill for run 8 in schedule 3 is alive.", "timestamp": 1757718540.015566, "uuid": "351ddc6e631c4cdb9bd818dbfa6fd8f8"}
2025-09-12T23:09:00 {"block_run_id": 15, "block_uuid": "qb_items_loader", "pipeline_run_id": 8, "pipeline_schedule_id": 3, "pipeline_uuid": "qb_items_backfill", "hostname": "370646b43903", "level": "INFO", "message": "Execute PipelineRun 8, BlockRun 15: pipeline qb_items_backfill block qb_items_loader", "timestamp": 1757718540.123504, "uuid": "00ec6b459b2b45028799360e08f28502"}
2025-09-12T23:09:01 {"block_run_id": 15, "block_uuid": "qb_items_loader", "pipeline_run_id": 8, "pipeline_schedule_id": 3, "pipeline_uuid": "qb_items_backfill", "hostname": "370646b43903", "level": "EXCEPTION", "message": "BlockRun 15 (block_uuid: qb_items_loader) failed.", "timestamp": 1757718541.63069, "uuid": "2e4472aca8fd4cf48c9642a4d53d29a7", "error": "Traceback (most recent call last):\n  File \"<string>\", line 75, in refresh_access_token\n  File \"/usr/local/lib/python3.10/site-packages/requests/models.py\", line 1021, in raise_for_status\n    raise HTTPError(http_error_msg, response=self)\nrequests.exceptions.HTTPError: 400 Client Error: Bad Request for url: https://oauth.platform.intuit.com/oauth2/v1/tokens/bearer\n\nThe above exception was the direct cause of the following exception:\n\nTraceback (most recent call last):\n  File \"/usr/local/lib/python3.10/site-packages/mage_ai/data_preparation/executors/block_executor.py\", line 647, in execute\n    result = __execute_with_retry()\n  File \"/usr/local/lib/python3.10/site-packages/mage_ai/shared/retry.py\", line 54, in retry_func\n    raise e\n  File \"/usr/local/lib/python3.10/site-packages/mage_ai/shared/retry.py\", line 38, in retry_func\n    return func(*args, **kwargs)\n  File \"/usr/local/lib/python3.10/site-packages/mage_ai/data_preparation/executors/block_executor.py\", line 621, in __execute_with_retry\n    return self._execute(\n  File \"/usr/local/lib/python3.10/site-packages/mage_ai/data_preparation/executors/block_executor.py\", line 1154, in _execute\n    result = self.block.execute_sync(\n  File \"/usr/local/lib/python3.10/site-packages/mage_ai/data_preparation/models/block/__init__.py\", line 1691, in execute_sync\n    return __execute()\n  File \"/usr/local/lib/python3.10/site-packages/mage_ai/data_preparation/models/block/__init__.py\", line 1668, in __execute\n    raise err\n  File \"/usr/local/lib/python3.10/site-packages/mage_ai/data_preparation/models/block/__init__.py\", line 1570, in __execute\n    output = self.execute_block(\n  File \"/usr/local/lib/python3.10/site-packages/mage_ai/data_preparation/models/block/__init__.py\", line 1910, in execute_block\n    outputs = self._execute_block(\n  File \"/usr/local/lib/python3.10/site-packages/mage_ai/data_preparation/models/block/__init__.py\", line 2073, in _execute_block\n    outputs = self.execute_block_function(\n  File \"/usr/local/lib/python3.10/site-packages/mage_ai/data_preparation/models/block/__init__.py\", line 2169, in execute_block_function\n    output = block_function_updated(*input_vars, **global_vars)\n  File \"<string>\", line 206, in load_data\n  File \"<string>\", line 77, in refresh_access_token\nRuntimeError: Error al refrescar token: 400 {\"error\":\"invalid_grant\"}\n", "error_stack": ["  File \"/usr/local/bin/mage\", line 8, in <module>\n    sys.exit(app())\n", "  File \"/usr/local/lib/python3.10/site-packages/typer/main.py\", line 311, in __call__\n    return get_command(self)(*args, **kwargs)\n", "  File \"/usr/local/lib/python3.10/site-packages/click/core.py\", line 1442, in __call__\n    return self.main(*args, **kwargs)\n", "  File \"/usr/local/lib/python3.10/site-packages/typer/core.py\", line 778, in main\n    return _main(\n", "  File \"/usr/local/lib/python3.10/site-packages/typer/core.py\", line 216, in _main\n    rv = self.invoke(ctx)\n", "  File \"/usr/local/lib/python3.10/site-packages/click/core.py\", line 1830, in invoke\n    return _process_result(sub_ctx.command.invoke(sub_ctx))\n", "  File \"/usr/local/lib/python3.10/site-packages/click/core.py\", line 1226, in invoke\n    return ctx.invoke(self.callback, **ctx.params)\n", "  File \"/usr/local/lib/python3.10/site-packages/click/core.py\", line 794, in invoke\n    return callback(*args, **kwargs)\n", "  File \"/usr/local/lib/python3.10/site-packages/typer/main.py\", line 683, in wrapper\n    return callback(**use_params)  # type: ignore\n", "  File \"/usr/local/lib/python3.10/site-packages/mage_ai/cli/main.py\", line 147, in start\n    start_server(\n", "  File \"/usr/local/lib/python3.10/site-packages/mage_ai/server/server.py\", line 809, in start_server\n    scheduler_manager.start_scheduler()\n", "  File \"/usr/local/lib/python3.10/site-packages/mage_ai/server/scheduler_manager.py\", line 108, in start_scheduler\n    proc.start()\n", "  File \"/usr/local/lib/python3.10/multiprocessing/process.py\", line 121, in start\n    self._popen = self._Popen(self)\n", "  File \"/usr/local/lib/python3.10/multiprocessing/context.py\", line 224, in _Popen\n    return _default_context.get_context().Process._Popen(process_obj)\n", "  File \"/usr/local/lib/python3.10/multiprocessing/context.py\", line 281, in _Popen\n    return Popen(process_obj)\n", "  File \"/usr/local/lib/python3.10/multiprocessing/popen_fork.py\", line 19, in __init__\n    self._launch(process_obj)\n", "  File \"/usr/local/lib/python3.10/multiprocessing/popen_fork.py\", line 71, in _launch\n    code = process_obj._bootstrap(parent_sentinel=child_r)\n", "  File \"/usr/local/lib/python3.10/multiprocessing/process.py\", line 314, in _bootstrap\n    self.run()\n", "  File \"/usr/local/lib/python3.10/multiprocessing/process.py\", line 108, in run\n    self._target(*self._args, **self._kwargs)\n", "  File \"/usr/local/lib/python3.10/site-packages/mage_ai/orchestration/db/process.py\", line 15, in start_session_and_run\n    results = target(*args)\n", "  File \"/usr/local/lib/python3.10/site-packages/mage_ai/server/scheduler_manager.py\", line 60, in run_scheduler\n    LoopTimeTrigger().start()\n", "  File \"/usr/local/lib/python3.10/site-packages/mage_ai/orchestration/triggers/loop_time_trigger.py\", line 14, in start\n    self.run()\n", "  File \"/usr/local/lib/python3.10/site-packages/mage_ai/orchestration/triggers/time_trigger.py\", line 11, in run\n    schedule_all()\n", "  File \"/usr/local/lib/python3.10/site-packages/mage_ai/orchestration/pipeline_scheduler_original.py\", line 1702, in schedule_all\n    PipelineScheduler(r).start()\n", "  File \"/usr/local/lib/python3.10/site-packages/mage_ai/orchestration/db/__init__.py\", line 159, in func_with_rollback\n    return func(*args, **kwargs)\n", "  File \"/usr/local/lib/python3.10/site-packages/mage_ai/orchestration/pipeline_scheduler_original.py\", line 197, in start\n    self.schedule()\n", "  File \"/usr/local/lib/python3.10/site-packages/mage_ai/orchestration/db/__init__.py\", line 159, in func_with_rollback\n    return func(*args, **kwargs)\n", "  File \"/usr/local/lib/python3.10/site-packages/mage_ai/orchestration/pipeline_scheduler_original.py\", line 333, in schedule\n    self.__schedule_blocks(block_runs)\n", "  File \"/usr/local/lib/python3.10/site-packages/mage_ai/orchestration/pipeline_scheduler_original.py\", line 640, in __schedule_blocks\n    job_manager.add_job(\n", "  File \"/usr/local/lib/python3.10/site-packages/mage_ai/orchestration/job_manager.py\", line 20, in add_job\n    self.queue.enqueue(job_id, target, *args, **kwargs)\n", "  File \"/usr/local/lib/python3.10/site-packages/mage_ai/orchestration/queue/process_queue.py\", line 122, in enqueue\n    self.start_worker_pool()\n", "  File \"/usr/local/lib/python3.10/site-packages/mage_ai/orchestration/queue/process_queue.py\", line 199, in start_worker_pool\n    self.worker_pool_proc.start()\n", "  File \"/usr/local/lib/python3.10/multiprocessing/process.py\", line 121, in start\n    self._popen = self._Popen(self)\n", "  File \"/usr/local/lib/python3.10/multiprocessing/context.py\", line 224, in _Popen\n    return _default_context.get_context().Process._Popen(process_obj)\n", "  File \"/usr/local/lib/python3.10/multiprocessing/context.py\", line 281, in _Popen\n    return Popen(process_obj)\n", "  File \"/usr/local/lib/python3.10/multiprocessing/popen_fork.py\", line 19, in __init__\n    self._launch(process_obj)\n", "  File \"/usr/local/lib/python3.10/multiprocessing/popen_fork.py\", line 71, in _launch\n    code = process_obj._bootstrap(parent_sentinel=child_r)\n", "  File \"/usr/local/lib/python3.10/multiprocessing/process.py\", line 314, in _bootstrap\n    self.run()\n", "  File \"/usr/local/lib/python3.10/multiprocessing/process.py\", line 108, in run\n    self._target(*self._args, **self._kwargs)\n", "  File \"/usr/local/lib/python3.10/site-packages/mage_ai/orchestration/queue/process_queue.py\", line 353, in poll_job_and_execute\n    worker.start()\n", "  File \"/usr/local/lib/python3.10/multiprocessing/process.py\", line 121, in start\n    self._popen = self._Popen(self)\n", "  File \"/usr/local/lib/python3.10/multiprocessing/context.py\", line 224, in _Popen\n    return _default_context.get_context().Process._Popen(process_obj)\n", "  File \"/usr/local/lib/python3.10/multiprocessing/context.py\", line 281, in _Popen\n    return Popen(process_obj)\n", "  File \"/usr/local/lib/python3.10/multiprocessing/popen_fork.py\", line 19, in __init__\n    self._launch(process_obj)\n", "  File \"/usr/local/lib/python3.10/multiprocessing/popen_fork.py\", line 71, in _launch\n    code = process_obj._bootstrap(parent_sentinel=child_r)\n", "  File \"/usr/local/lib/python3.10/multiprocessing/process.py\", line 314, in _bootstrap\n    self.run()\n", "  File \"/usr/local/lib/python3.10/site-packages/newrelic/api/background_task.py\", line 117, in wrapper\n    return wrapped(*args, **kwargs)\n", "  File \"/usr/local/lib/python3.10/site-packages/mage_ai/orchestration/queue/process_queue.py\", line 317, in run\n    start_session_and_run(args[1], *args[2], **args[3])\n", "  File \"/usr/local/lib/python3.10/site-packages/mage_ai/orchestration/db/process.py\", line 15, in start_session_and_run\n    results = target(*args)\n", "  File \"/usr/local/lib/python3.10/site-packages/mage_ai/orchestration/pipeline_scheduler_original.py\", line 1235, in run_block\n    return ExecutorFactory.get_block_executor(\n", "  File \"/usr/local/lib/python3.10/site-packages/mage_ai/data_preparation/executors/block_executor.py\", line 682, in execute\n    on_failure(\n", "  File \"/usr/local/lib/python3.10/site-packages/mage_ai/orchestration/db/__init__.py\", line 159, in func_with_rollback\n    return func(*args, **kwargs)\n", "  File \"/usr/local/lib/python3.10/site-packages/mage_ai/orchestration/pipeline_scheduler_original.py\", line 464, in on_block_failure\n    self.logger.exception(\n", "  File \"/usr/local/lib/python3.10/site-packages/mage_ai/data_preparation/logging/logger.py\", line 30, in exception\n    self.__send_message('exception', message, **kwargs)\n", "  File \"/usr/local/lib/python3.10/site-packages/mage_ai/data_preparation/logging/logger.py\", line 65, in __send_message\n    data['error_stack'] = traceback.format_stack()\n"], "error_stacktrace": "Error al refrescar token: 400 {\"error\":\"invalid_grant\"}"}
Traceback (most recent call last):
  File "<string>", line 75, in refresh_access_token
  File "/usr/local/lib/python3.10/site-packages/requests/models.py", line 1021, in raise_for_status
    raise HTTPError(http_error_msg, response=self)
requests.exceptions.HTTPError: 400 Client Error: Bad Request for url: https://oauth.platform.intuit.com/oauth2/v1/tokens/bearer

The above exception was the direct cause of the following exception:

Traceback (most recent call last):
  File "/usr/local/lib/python3.10/site-packages/mage_ai/data_preparation/executors/block_executor.py", line 647, in execute
    result = __execute_with_retry()
  File "/usr/local/lib/python3.10/site-packages/mage_ai/shared/retry.py", line 54, in retry_func
    raise e
  File "/usr/local/lib/python3.10/site-packages/mage_ai/shared/retry.py", line 38, in retry_func
    return func(*args, **kwargs)
  File "/usr/local/lib/python3.10/site-packages/mage_ai/data_preparation/executors/block_executor.py", line 621, in __execute_with_retry
    return self._execute(
  File "/usr/local/lib/python3.10/site-packages/mage_ai/data_preparation/executors/block_executor.py", line 1154, in _execute
    result = self.block.execute_sync(
  File "/usr/local/lib/python3.10/site-packages/mage_ai/data_preparation/models/block/__init__.py", line 1691, in execute_sync
    return __execute()
  File "/usr/local/lib/python3.10/site-packages/mage_ai/data_preparation/models/block/__init__.py", line 1668, in __execute
    raise err
  File "/usr/local/lib/python3.10/site-packages/mage_ai/data_preparation/models/block/__init__.py", line 1570, in __execute
    output = self.execute_block(
  File "/usr/local/lib/python3.10/site-packages/mage_ai/data_preparation/models/block/__init__.py", line 1910, in execute_block
    outputs = self._execute_block(
  File "/usr/local/lib/python3.10/site-packages/mage_ai/data_preparation/models/block/__init__.py", line 2073, in _execute_block
    outputs = self.execute_block_function(
  File "/usr/local/lib/python3.10/site-packages/mage_ai/data_preparation/models/block/__init__.py", line 2169, in execute_block_function
    output = block_function_updated(*input_vars, **global_vars)
  File "<string>", line 206, in load_data
  File "<string>", line 77, in refresh_access_token
RuntimeError: Error al refrescar token: 400 {"error":"invalid_grant"}
2025-09-12T23:09:09 {"cpu": 0.25537109375, "cpu_total": 20, "cpu_usage": 0.0127685546875, "memory": 2017.0, "memory_total": 9804.0, "memory_usage": 0.20573235414116686, "pipeline_run_id": 8, "pipeline_schedule_id": 3, "pipeline_uuid": "qb_items_backfill", "hostname": "370646b43903", "level": "INFO", "message": "Pipeline qb_items_backfill for run 8 in schedule 3 is alive.", "timestamp": 1757718549.591594, "uuid": "adac40a6578944428ffe57e166f7f92d"}
2025-09-12T23:11:40 {"cpu": 0.3095703125, "cpu_total": 20, "cpu_usage": 0.015478515625, "memory": 2080.0, "memory_total": 9804.0, "memory_usage": 0.21215830273357814, "pipeline_run_id": 11, "pipeline_schedule_id": 3, "pipeline_uuid": "qb_items_backfill", "hostname": "370646b43903", "level": "INFO", "message": "Pipeline qb_items_backfill for run 11 in schedule 3 is alive.", "timestamp": 1757718700.313858, "uuid": "ee1ea159607b4fa0a2e4b513dde45aea"}
2025-09-12T23:11:41 {"cpu": 0.3095703125, "cpu_total": 20, "cpu_usage": 0.015478515625, "memory": 2080.0, "memory_total": 9804.0, "memory_usage": 0.21215830273357814, "pipeline_run_id": 11, "pipeline_schedule_id": 3, "pipeline_uuid": "qb_items_backfill", "hostname": "370646b43903", "level": "INFO", "message": "Pipeline qb_items_backfill for run 11 in schedule 3 is alive.", "timestamp": 1757718701.309556, "uuid": "243b3deffaf5495482f74f1d84d56a3b"}
2025-09-12T23:11:41 {"block_run_id": 21, "block_uuid": "qb_items_loader", "pipeline_run_id": 11, "pipeline_schedule_id": 3, "pipeline_uuid": "qb_items_backfill", "hostname": "370646b43903", "level": "INFO", "message": "Execute PipelineRun 11, BlockRun 21: pipeline qb_items_backfill block qb_items_loader", "timestamp": 1757718701.799849, "uuid": "8926a153a6f343f0a91bf37b2e0b023e"}
2025-09-12T23:11:50 {"cpu": 0.31689453125, "cpu_total": 20, "cpu_usage": 0.0158447265625, "memory": 2081.0, "memory_total": 9804.0, "memory_usage": 0.21226030191758466, "pipeline_run_id": 11, "pipeline_schedule_id": 3, "pipeline_uuid": "qb_items_backfill", "hostname": "370646b43903", "level": "INFO", "message": "Pipeline qb_items_backfill for run 11 in schedule 3 is alive.", "timestamp": 1757718710.279346, "uuid": "602ae605d4b6410cad42fbe7dcd4a286"}
2025-09-12T23:12:00 {"cpu": 0.31494140625, "cpu_total": 20, "cpu_usage": 0.0157470703125, "memory": 2081.0, "memory_total": 9804.0, "memory_usage": 0.21226030191758466, "pipeline_run_id": 11, "pipeline_schedule_id": 3, "pipeline_uuid": "qb_items_backfill", "hostname": "370646b43903", "level": "INFO", "message": "Pipeline qb_items_backfill for run 11 in schedule 3 is alive.", "timestamp": 1757718720.04526, "uuid": "bffe0f0b2e8d4bcaa1079bf1ab8ca44c"}
2025-09-12T23:12:02 {"block_run_id": 21, "block_uuid": "qb_items_loader", "pipeline_run_id": 11, "pipeline_schedule_id": 3, "pipeline_uuid": "qb_items_backfill", "hostname": "370646b43903", "level": "INFO", "message": "BlockRun 21 (block_uuid: qb_items_loader) completes.", "timestamp": 1757718722.60121, "uuid": "0c6a3f5bfd63407289205852bf871858"}
2025-09-12T23:12:09 {"cpu": 0.31689453125, "cpu_total": 20, "cpu_usage": 0.0158447265625, "memory": 2022.0, "memory_total": 9804.0, "memory_usage": 0.2062423500611995, "pipeline_run_id": 11, "pipeline_schedule_id": 3, "pipeline_uuid": "qb_items_backfill", "hostname": "370646b43903", "level": "INFO", "message": "Pipeline qb_items_backfill for run 11 in schedule 3 is alive.", "timestamp": 1757718729.571848, "uuid": "4695f46b87c84b6bb7ba6aedfdd624cb"}
2025-09-12T23:12:10 {"block_run_id": 22, "block_uuid": "qb_items_exporter", "pipeline_run_id": 11, "pipeline_schedule_id": 3, "pipeline_uuid": "qb_items_backfill", "hostname": "370646b43903", "level": "INFO", "message": "Execute PipelineRun 11, BlockRun 22: pipeline qb_items_backfill block qb_items_exporter", "timestamp": 1757718730.119323, "uuid": "273f146767594612ae372aefd1d10201"}
2025-09-12T23:12:10 {"block_run_id": 22, "block_uuid": "qb_items_exporter", "pipeline_run_id": 11, "pipeline_schedule_id": 3, "pipeline_uuid": "qb_items_backfill", "hostname": "370646b43903", "level": "EXCEPTION", "message": "BlockRun 22 (block_uuid: qb_items_exporter) failed.", "timestamp": 1757718730.35377, "uuid": "8d589b3204694432b908934456f6d702", "error": "Traceback (most recent call last):\n  File \"/usr/local/lib/python3.10/site-packages/mage_ai/data_preparation/executors/block_executor.py\", line 647, in execute\n    result = __execute_with_retry()\n  File \"/usr/local/lib/python3.10/site-packages/mage_ai/shared/retry.py\", line 54, in retry_func\n    raise e\n  File \"/usr/local/lib/python3.10/site-packages/mage_ai/shared/retry.py\", line 38, in retry_func\n    return func(*args, **kwargs)\n  File \"/usr/local/lib/python3.10/site-packages/mage_ai/data_preparation/executors/block_executor.py\", line 621, in __execute_with_retry\n    return self._execute(\n  File \"/usr/local/lib/python3.10/site-packages/mage_ai/data_preparation/executors/block_executor.py\", line 1154, in _execute\n    result = self.block.execute_sync(\n  File \"/usr/local/lib/python3.10/site-packages/mage_ai/data_preparation/models/block/__init__.py\", line 1691, in execute_sync\n    return __execute()\n  File \"/usr/local/lib/python3.10/site-packages/mage_ai/data_preparation/models/block/__init__.py\", line 1668, in __execute\n    raise err\n  File \"/usr/local/lib/python3.10/site-packages/mage_ai/data_preparation/models/block/__init__.py\", line 1570, in __execute\n    output = self.execute_block(\n  File \"/usr/local/lib/python3.10/site-packages/mage_ai/data_preparation/models/block/__init__.py\", line 1910, in execute_block\n    outputs = self._execute_block(\n  File \"/usr/local/lib/python3.10/site-packages/mage_ai/data_preparation/models/block/__init__.py\", line 2041, in _execute_block\n    exec(self.content, results)\n  File \"<string>\", line 111\n    \"source\": \"mage\",\n            ^\nSyntaxError: invalid syntax\n", "error_stack": ["  File \"/usr/local/bin/mage\", line 8, in <module>\n    sys.exit(app())\n", "  File \"/usr/local/lib/python3.10/site-packages/typer/main.py\", line 311, in __call__\n    return get_command(self)(*args, **kwargs)\n", "  File \"/usr/local/lib/python3.10/site-packages/click/core.py\", line 1442, in __call__\n    return self.main(*args, **kwargs)\n", "  File \"/usr/local/lib/python3.10/site-packages/typer/core.py\", line 778, in main\n    return _main(\n", "  File \"/usr/local/lib/python3.10/site-packages/typer/core.py\", line 216, in _main\n    rv = self.invoke(ctx)\n", "  File \"/usr/local/lib/python3.10/site-packages/click/core.py\", line 1830, in invoke\n    return _process_result(sub_ctx.command.invoke(sub_ctx))\n", "  File \"/usr/local/lib/python3.10/site-packages/click/core.py\", line 1226, in invoke\n    return ctx.invoke(self.callback, **ctx.params)\n", "  File \"/usr/local/lib/python3.10/site-packages/click/core.py\", line 794, in invoke\n    return callback(*args, **kwargs)\n", "  File \"/usr/local/lib/python3.10/site-packages/typer/main.py\", line 683, in wrapper\n    return callback(**use_params)  # type: ignore\n", "  File \"/usr/local/lib/python3.10/site-packages/mage_ai/cli/main.py\", line 147, in start\n    start_server(\n", "  File \"/usr/local/lib/python3.10/site-packages/mage_ai/server/server.py\", line 809, in start_server\n    scheduler_manager.start_scheduler()\n", "  File \"/usr/local/lib/python3.10/site-packages/mage_ai/server/scheduler_manager.py\", line 108, in start_scheduler\n    proc.start()\n", "  File \"/usr/local/lib/python3.10/multiprocessing/process.py\", line 121, in start\n    self._popen = self._Popen(self)\n", "  File \"/usr/local/lib/python3.10/multiprocessing/context.py\", line 224, in _Popen\n    return _default_context.get_context().Process._Popen(process_obj)\n", "  File \"/usr/local/lib/python3.10/multiprocessing/context.py\", line 281, in _Popen\n    return Popen(process_obj)\n", "  File \"/usr/local/lib/python3.10/multiprocessing/popen_fork.py\", line 19, in __init__\n    self._launch(process_obj)\n", "  File \"/usr/local/lib/python3.10/multiprocessing/popen_fork.py\", line 71, in _launch\n    code = process_obj._bootstrap(parent_sentinel=child_r)\n", "  File \"/usr/local/lib/python3.10/multiprocessing/process.py\", line 314, in _bootstrap\n    self.run()\n", "  File \"/usr/local/lib/python3.10/multiprocessing/process.py\", line 108, in run\n    self._target(*self._args, **self._kwargs)\n", "  File \"/usr/local/lib/python3.10/site-packages/mage_ai/orchestration/db/process.py\", line 15, in start_session_and_run\n    results = target(*args)\n", "  File \"/usr/local/lib/python3.10/site-packages/mage_ai/server/scheduler_manager.py\", line 60, in run_scheduler\n    LoopTimeTrigger().start()\n", "  File \"/usr/local/lib/python3.10/site-packages/mage_ai/orchestration/triggers/loop_time_trigger.py\", line 14, in start\n    self.run()\n", "  File \"/usr/local/lib/python3.10/site-packages/mage_ai/orchestration/triggers/time_trigger.py\", line 11, in run\n    schedule_all()\n", "  File \"/usr/local/lib/python3.10/site-packages/mage_ai/orchestration/pipeline_scheduler_original.py\", line 1730, in schedule_all\n    PipelineScheduler(r).schedule()\n", "  File \"/usr/local/lib/python3.10/site-packages/mage_ai/orchestration/db/__init__.py\", line 159, in func_with_rollback\n    return func(*args, **kwargs)\n", "  File \"/usr/local/lib/python3.10/site-packages/mage_ai/orchestration/pipeline_scheduler_original.py\", line 333, in schedule\n    self.__schedule_blocks(block_runs)\n", "  File \"/usr/local/lib/python3.10/site-packages/mage_ai/orchestration/pipeline_scheduler_original.py\", line 640, in __schedule_blocks\n    job_manager.add_job(\n", "  File \"/usr/local/lib/python3.10/site-packages/mage_ai/orchestration/job_manager.py\", line 20, in add_job\n    self.queue.enqueue(job_id, target, *args, **kwargs)\n", "  File \"/usr/local/lib/python3.10/site-packages/mage_ai/orchestration/queue/process_queue.py\", line 122, in enqueue\n    self.start_worker_pool()\n", "  File \"/usr/local/lib/python3.10/site-packages/mage_ai/orchestration/queue/process_queue.py\", line 199, in start_worker_pool\n    self.worker_pool_proc.start()\n", "  File \"/usr/local/lib/python3.10/multiprocessing/process.py\", line 121, in start\n    self._popen = self._Popen(self)\n", "  File \"/usr/local/lib/python3.10/multiprocessing/context.py\", line 224, in _Popen\n    return _default_context.get_context().Process._Popen(process_obj)\n", "  File \"/usr/local/lib/python3.10/multiprocessing/context.py\", line 281, in _Popen\n    return Popen(process_obj)\n", "  File \"/usr/local/lib/python3.10/multiprocessing/popen_fork.py\", line 19, in __init__\n    self._launch(process_obj)\n", "  File \"/usr/local/lib/python3.10/multiprocessing/popen_fork.py\", line 71, in _launch\n    code = process_obj._bootstrap(parent_sentinel=child_r)\n", "  File \"/usr/local/lib/python3.10/multiprocessing/process.py\", line 314, in _bootstrap\n    self.run()\n", "  File \"/usr/local/lib/python3.10/multiprocessing/process.py\", line 108, in run\n    self._target(*self._args, **self._kwargs)\n", "  File \"/usr/local/lib/python3.10/site-packages/mage_ai/orchestration/queue/process_queue.py\", line 353, in poll_job_and_execute\n    worker.start()\n", "  File \"/usr/local/lib/python3.10/multiprocessing/process.py\", line 121, in start\n    self._popen = self._Popen(self)\n", "  File \"/usr/local/lib/python3.10/multiprocessing/context.py\", line 224, in _Popen\n    return _default_context.get_context().Process._Popen(process_obj)\n", "  File \"/usr/local/lib/python3.10/multiprocessing/context.py\", line 281, in _Popen\n    return Popen(process_obj)\n", "  File \"/usr/local/lib/python3.10/multiprocessing/popen_fork.py\", line 19, in __init__\n    self._launch(process_obj)\n", "  File \"/usr/local/lib/python3.10/multiprocessing/popen_fork.py\", line 71, in _launch\n    code = process_obj._bootstrap(parent_sentinel=child_r)\n", "  File \"/usr/local/lib/python3.10/multiprocessing/process.py\", line 314, in _bootstrap\n    self.run()\n", "  File \"/usr/local/lib/python3.10/site-packages/newrelic/api/background_task.py\", line 117, in wrapper\n    return wrapped(*args, **kwargs)\n", "  File \"/usr/local/lib/python3.10/site-packages/mage_ai/orchestration/queue/process_queue.py\", line 317, in run\n    start_session_and_run(args[1], *args[2], **args[3])\n", "  File \"/usr/local/lib/python3.10/site-packages/mage_ai/orchestration/db/process.py\", line 15, in start_session_and_run\n    results = target(*args)\n", "  File \"/usr/local/lib/python3.10/site-packages/mage_ai/orchestration/pipeline_scheduler_original.py\", line 1235, in run_block\n    return ExecutorFactory.get_block_executor(\n", "  File \"/usr/local/lib/python3.10/site-packages/mage_ai/data_preparation/executors/block_executor.py\", line 682, in execute\n    on_failure(\n", "  File \"/usr/local/lib/python3.10/site-packages/mage_ai/orchestration/db/__init__.py\", line 159, in func_with_rollback\n    return func(*args, **kwargs)\n", "  File \"/usr/local/lib/python3.10/site-packages/mage_ai/orchestration/pipeline_scheduler_original.py\", line 464, in on_block_failure\n    self.logger.exception(\n", "  File \"/usr/local/lib/python3.10/site-packages/mage_ai/data_preparation/logging/logger.py\", line 30, in exception\n    self.__send_message('exception', message, **kwargs)\n", "  File \"/usr/local/lib/python3.10/site-packages/mage_ai/data_preparation/logging/logger.py\", line 65, in __send_message\n    data['error_stack'] = traceback.format_stack()\n"], "error_stacktrace": "invalid syntax (<string>, line 111)"}
Traceback (most recent call last):
  File "/usr/local/lib/python3.10/site-packages/mage_ai/data_preparation/executors/block_executor.py", line 647, in execute
    result = __execute_with_retry()
  File "/usr/local/lib/python3.10/site-packages/mage_ai/shared/retry.py", line 54, in retry_func
    raise e
  File "/usr/local/lib/python3.10/site-packages/mage_ai/shared/retry.py", line 38, in retry_func
    return func(*args, **kwargs)
  File "/usr/local/lib/python3.10/site-packages/mage_ai/data_preparation/executors/block_executor.py", line 621, in __execute_with_retry
    return self._execute(
  File "/usr/local/lib/python3.10/site-packages/mage_ai/data_preparation/executors/block_executor.py", line 1154, in _execute
    result = self.block.execute_sync(
  File "/usr/local/lib/python3.10/site-packages/mage_ai/data_preparation/models/block/__init__.py", line 1691, in execute_sync
    return __execute()
  File "/usr/local/lib/python3.10/site-packages/mage_ai/data_preparation/models/block/__init__.py", line 1668, in __execute
    raise err
  File "/usr/local/lib/python3.10/site-packages/mage_ai/data_preparation/models/block/__init__.py", line 1570, in __execute
    output = self.execute_block(
  File "/usr/local/lib/python3.10/site-packages/mage_ai/data_preparation/models/block/__init__.py", line 1910, in execute_block
    outputs = self._execute_block(
  File "/usr/local/lib/python3.10/site-packages/mage_ai/data_preparation/models/block/__init__.py", line 2041, in _execute_block
    exec(self.content, results)
  File "<string>", line 111
    "source": "mage",
            ^
SyntaxError: invalid syntax
2025-09-12T23:12:20 {"cpu": 0.33349609375, "cpu_total": 20, "cpu_usage": 0.0166748046875, "memory": 2024.0, "memory_total": 9804.0, "memory_usage": 0.20644634842921256, "pipeline_run_id": 11, "pipeline_schedule_id": 3, "pipeline_uuid": "qb_items_backfill", "hostname": "370646b43903", "level": "INFO", "message": "Pipeline qb_items_backfill for run 11 in schedule 3 is alive.", "timestamp": 1757718740.232801, "uuid": "d9a6f0f04b364a59b6af42dbf448a89b"}
2025-09-12T23:14:22 {"cpu": 0.451171875, "cpu_total": 20, "cpu_usage": 0.02255859375, "memory": 2079.0, "memory_total": 9804.0, "memory_usage": 0.2120563035495716, "pipeline_run_id": 14, "pipeline_schedule_id": 3, "pipeline_uuid": "qb_items_backfill", "hostname": "370646b43903", "level": "INFO", "message": "Pipeline qb_items_backfill for run 14 in schedule 3 is alive.", "timestamp": 1757718862.096935, "uuid": "0b40077015eb49c487c443cfe6b9c4da"}
2025-09-12T23:14:22 {"cpu": 0.451171875, "cpu_total": 20, "cpu_usage": 0.02255859375, "memory": 2120.0, "memory_total": 9804.0, "memory_usage": 0.21623827009383925, "pipeline_run_id": 14, "pipeline_schedule_id": 3, "pipeline_uuid": "qb_items_backfill", "hostname": "370646b43903", "level": "INFO", "message": "Pipeline qb_items_backfill for run 14 in schedule 3 is alive.", "timestamp": 1757718862.844038, "uuid": "ab5232d5d9b7456a856c71e020fdf460"}
2025-09-12T23:14:22 {"block_run_id": 27, "block_uuid": "qb_items_loader", "pipeline_run_id": 14, "pipeline_schedule_id": 3, "pipeline_uuid": "qb_items_backfill", "hostname": "370646b43903", "level": "INFO", "message": "Execute PipelineRun 14, BlockRun 27: pipeline qb_items_backfill block qb_items_loader", "timestamp": 1757718862.849139, "uuid": "e7b02e53890f4c2ab7541c7174762c49"}
2025-09-12T23:14:30 {"cpu": 0.4951171875, "cpu_total": 20, "cpu_usage": 0.024755859375, "memory": 2115.0, "memory_total": 9804.0, "memory_usage": 0.2157282741738066, "pipeline_run_id": 14, "pipeline_schedule_id": 3, "pipeline_uuid": "qb_items_backfill", "hostname": "370646b43903", "level": "INFO", "message": "Pipeline qb_items_backfill for run 14 in schedule 3 is alive.", "timestamp": 1757718870.626949, "uuid": "d12565d3c39f4ec3ad83ffc7a53e615c"}
2025-09-12T23:14:40 {"block_run_id": 27, "block_uuid": "qb_items_loader", "pipeline_run_id": 14, "pipeline_schedule_id": 3, "pipeline_uuid": "qb_items_backfill", "hostname": "370646b43903", "level": "INFO", "message": "BlockRun 27 (block_uuid: qb_items_loader) completes.", "timestamp": 1757718880.695564, "uuid": "7d676e9e156c40f6b2770352ef21036d"}
2025-09-12T23:14:42 {"cpu": 0.51171875, "cpu_total": 20, "cpu_usage": 0.0255859375, "memory": 2053.0, "memory_total": 9804.0, "memory_usage": 0.20940432476540188, "pipeline_run_id": 14, "pipeline_schedule_id": 3, "pipeline_uuid": "qb_items_backfill", "hostname": "370646b43903", "level": "INFO", "message": "Pipeline qb_items_backfill for run 14 in schedule 3 is alive.", "timestamp": 1757718882.537032, "uuid": "986f25d3c0444918bc83262d3ed425f6"}
2025-09-12T23:14:43 {"block_run_id": 28, "block_uuid": "qb_items_exporter", "pipeline_run_id": 14, "pipeline_schedule_id": 3, "pipeline_uuid": "qb_items_backfill", "hostname": "370646b43903", "level": "INFO", "message": "Execute PipelineRun 14, BlockRun 28: pipeline qb_items_backfill block qb_items_exporter", "timestamp": 1757718883.728026, "uuid": "b1ebc3e75bb048079e4792b0028dc8e7"}
2025-09-12T23:14:45 {"block_run_id": 28, "block_uuid": "qb_items_exporter", "pipeline_run_id": 14, "pipeline_schedule_id": 3, "pipeline_uuid": "qb_items_backfill", "hostname": "370646b43903", "level": "INFO", "message": "BlockRun 28 (block_uuid: qb_items_exporter) completes.", "timestamp": 1757718885.984233, "uuid": "a468260accb64cbc9716f1761f2ec780"}
2025-09-12T23:14:50 {"cpu": 0.54443359375, "cpu_total": 20, "cpu_usage": 0.0272216796875, "memory": 2020.0, "memory_total": 9804.0, "memory_usage": 0.20603835169318646, "pipeline_run_id": 14, "pipeline_schedule_id": 3, "pipeline_uuid": "qb_items_backfill", "hostname": "370646b43903", "level": "INFO", "message": "Pipeline qb_items_backfill for run 14 in schedule 3 is alive.", "timestamp": 1757718890.553064, "uuid": "7e901339584f4b7e96d5ac8836934f95"}
