2025-09-13T00:00:27 {"cpu": 0.15283203125, "cpu_total": 20, "cpu_usage": 0.0076416015625, "memory": 2081.0, "memory_total": 9804.0, "memory_usage": 0.21226030191758466, "pipeline_run_id": 21, "pipeline_schedule_id": 2, "pipeline_uuid": "qb_invoices_bacfill", "hostname": "370646b43903", "level": "INFO", "message": "Pipeline qb_invoices_bacfill for run 21 in schedule 2 is alive.", "timestamp": 1757721627.064448, "uuid": "1c3bb8a428be470d8f94fdd9a62b8332"}
2025-09-13T00:00:27 {"cpu": 0.15283203125, "cpu_total": 20, "cpu_usage": 0.0076416015625, "memory": 2116.0, "memory_total": 9804.0, "memory_usage": 0.21583027335781313, "pipeline_run_id": 21, "pipeline_schedule_id": 2, "pipeline_uuid": "qb_invoices_bacfill", "hostname": "370646b43903", "level": "INFO", "message": "Pipeline qb_invoices_bacfill for run 21 in schedule 2 is alive.", "timestamp": 1757721627.271056, "uuid": "81bc22e9a6a54f54b21dc9697fd73363"}
2025-09-13T00:00:27 {"block_run_id": 41, "block_uuid": "qb_invoices_loader", "pipeline_run_id": 21, "pipeline_schedule_id": 2, "pipeline_uuid": "qb_invoices_bacfill", "hostname": "370646b43903", "level": "INFO", "message": "Execute PipelineRun 21, BlockRun 41: pipeline qb_invoices_bacfill block qb_invoices_loader", "timestamp": 1757721627.318853, "uuid": "70a8f0ddfb3f485a9e4bcdb39257cb06"}
2025-09-13T00:00:36 {"cpu": 0.162109375, "cpu_total": 20, "cpu_usage": 0.00810546875, "memory": 2122.0, "memory_total": 9804.0, "memory_usage": 0.2164422684618523, "pipeline_run_id": 21, "pipeline_schedule_id": 2, "pipeline_uuid": "qb_invoices_bacfill", "hostname": "370646b43903", "level": "INFO", "message": "Pipeline qb_invoices_bacfill for run 21 in schedule 2 is alive.", "timestamp": 1757721636.514355, "uuid": "cadf46f478e34ec395716e33a51064a1"}
2025-09-13T00:00:41 {"block_run_id": 41, "block_uuid": "qb_invoices_loader", "pipeline_run_id": 21, "pipeline_schedule_id": 2, "pipeline_uuid": "qb_invoices_bacfill", "hostname": "370646b43903", "level": "INFO", "message": "BlockRun 41 (block_uuid: qb_invoices_loader) completes.", "timestamp": 1757721641.572623, "uuid": "d9e0e102be634159a3c6b6a5e633f9c0"}
2025-09-13T00:00:46 {"cpu": 0.16015625, "cpu_total": 20, "cpu_usage": 0.0080078125, "memory": 2068.0, "memory_total": 9804.0, "memory_usage": 0.2109343125254998, "pipeline_run_id": 21, "pipeline_schedule_id": 2, "pipeline_uuid": "qb_invoices_bacfill", "hostname": "370646b43903", "level": "INFO", "message": "Pipeline qb_invoices_bacfill for run 21 in schedule 2 is alive.", "timestamp": 1757721646.718933, "uuid": "651493651bf2477d91c824d170d72210"}
2025-09-13T00:00:46 {"block_run_id": 42, "block_uuid": "qb_invoices_exporter", "pipeline_run_id": 21, "pipeline_schedule_id": 2, "pipeline_uuid": "qb_invoices_bacfill", "hostname": "370646b43903", "level": "INFO", "message": "Execute PipelineRun 21, BlockRun 42: pipeline qb_invoices_bacfill block qb_invoices_exporter", "timestamp": 1757721646.91516, "uuid": "52e0e033d1fc4fce87fb4e5a690e9a4d"}
2025-09-13T00:00:47 {"block_run_id": 42, "block_uuid": "qb_invoices_exporter", "pipeline_run_id": 21, "pipeline_schedule_id": 2, "pipeline_uuid": "qb_invoices_bacfill", "hostname": "370646b43903", "level": "EXCEPTION", "message": "BlockRun 42 (block_uuid: qb_invoices_exporter) failed.", "timestamp": 1757721647.410069, "uuid": "8b6bc7284b7342dd87760ebe515a7653", "error": "Traceback (most recent call last):\n  File \"/usr/local/lib/python3.10/site-packages/mage_ai/data_preparation/executors/block_executor.py\", line 647, in execute\n    result = __execute_with_retry()\n  File \"/usr/local/lib/python3.10/site-packages/mage_ai/shared/retry.py\", line 54, in retry_func\n    raise e\n  File \"/usr/local/lib/python3.10/site-packages/mage_ai/shared/retry.py\", line 38, in retry_func\n    return func(*args, **kwargs)\n  File \"/usr/local/lib/python3.10/site-packages/mage_ai/data_preparation/executors/block_executor.py\", line 621, in __execute_with_retry\n    return self._execute(\n  File \"/usr/local/lib/python3.10/site-packages/mage_ai/data_preparation/executors/block_executor.py\", line 1154, in _execute\n    result = self.block.execute_sync(\n  File \"/usr/local/lib/python3.10/site-packages/mage_ai/data_preparation/models/block/__init__.py\", line 1691, in execute_sync\n    return __execute()\n  File \"/usr/local/lib/python3.10/site-packages/mage_ai/data_preparation/models/block/__init__.py\", line 1668, in __execute\n    raise err\n  File \"/usr/local/lib/python3.10/site-packages/mage_ai/data_preparation/models/block/__init__.py\", line 1570, in __execute\n    output = self.execute_block(\n  File \"/usr/local/lib/python3.10/site-packages/mage_ai/data_preparation/models/block/__init__.py\", line 1910, in execute_block\n    outputs = self._execute_block(\n  File \"/usr/local/lib/python3.10/site-packages/mage_ai/data_preparation/models/block/__init__.py\", line 2073, in _execute_block\n    outputs = self.execute_block_function(\n  File \"/usr/local/lib/python3.10/site-packages/mage_ai/data_preparation/models/block/__init__.py\", line 2169, in execute_block_function\n    output = block_function_updated(*input_vars, **global_vars)\n  File \"<string>\", line 122, in export_invoices_to_postgres\n  File \"/usr/local/lib/python3.10/site-packages/psycopg2/extras.py\", line 1267, in execute_values\n    parts.append(cur.mogrify(template, args))\nIndexError: tuple index out of range\n", "error_stack": ["  File \"/usr/local/bin/mage\", line 8, in <module>\n    sys.exit(app())\n", "  File \"/usr/local/lib/python3.10/site-packages/typer/main.py\", line 311, in __call__\n    return get_command(self)(*args, **kwargs)\n", "  File \"/usr/local/lib/python3.10/site-packages/click/core.py\", line 1442, in __call__\n    return self.main(*args, **kwargs)\n", "  File \"/usr/local/lib/python3.10/site-packages/typer/core.py\", line 778, in main\n    return _main(\n", "  File \"/usr/local/lib/python3.10/site-packages/typer/core.py\", line 216, in _main\n    rv = self.invoke(ctx)\n", "  File \"/usr/local/lib/python3.10/site-packages/click/core.py\", line 1830, in invoke\n    return _process_result(sub_ctx.command.invoke(sub_ctx))\n", "  File \"/usr/local/lib/python3.10/site-packages/click/core.py\", line 1226, in invoke\n    return ctx.invoke(self.callback, **ctx.params)\n", "  File \"/usr/local/lib/python3.10/site-packages/click/core.py\", line 794, in invoke\n    return callback(*args, **kwargs)\n", "  File \"/usr/local/lib/python3.10/site-packages/typer/main.py\", line 683, in wrapper\n    return callback(**use_params)  # type: ignore\n", "  File \"/usr/local/lib/python3.10/site-packages/mage_ai/cli/main.py\", line 147, in start\n    start_server(\n", "  File \"/usr/local/lib/python3.10/site-packages/mage_ai/server/server.py\", line 809, in start_server\n    scheduler_manager.start_scheduler()\n", "  File \"/usr/local/lib/python3.10/site-packages/mage_ai/server/scheduler_manager.py\", line 108, in start_scheduler\n    proc.start()\n", "  File \"/usr/local/lib/python3.10/multiprocessing/process.py\", line 121, in start\n    self._popen = self._Popen(self)\n", "  File \"/usr/local/lib/python3.10/multiprocessing/context.py\", line 224, in _Popen\n    return _default_context.get_context().Process._Popen(process_obj)\n", "  File \"/usr/local/lib/python3.10/multiprocessing/context.py\", line 281, in _Popen\n    return Popen(process_obj)\n", "  File \"/usr/local/lib/python3.10/multiprocessing/popen_fork.py\", line 19, in __init__\n    self._launch(process_obj)\n", "  File \"/usr/local/lib/python3.10/multiprocessing/popen_fork.py\", line 71, in _launch\n    code = process_obj._bootstrap(parent_sentinel=child_r)\n", "  File \"/usr/local/lib/python3.10/multiprocessing/process.py\", line 314, in _bootstrap\n    self.run()\n", "  File \"/usr/local/lib/python3.10/multiprocessing/process.py\", line 108, in run\n    self._target(*self._args, **self._kwargs)\n", "  File \"/usr/local/lib/python3.10/site-packages/mage_ai/orchestration/db/process.py\", line 15, in start_session_and_run\n    results = target(*args)\n", "  File \"/usr/local/lib/python3.10/site-packages/mage_ai/server/scheduler_manager.py\", line 60, in run_scheduler\n    LoopTimeTrigger().start()\n", "  File \"/usr/local/lib/python3.10/site-packages/mage_ai/orchestration/triggers/loop_time_trigger.py\", line 14, in start\n    self.run()\n", "  File \"/usr/local/lib/python3.10/site-packages/mage_ai/orchestration/triggers/time_trigger.py\", line 11, in run\n    schedule_all()\n", "  File \"/usr/local/lib/python3.10/site-packages/mage_ai/orchestration/pipeline_scheduler_original.py\", line 1730, in schedule_all\n    PipelineScheduler(r).schedule()\n", "  File \"/usr/local/lib/python3.10/site-packages/mage_ai/orchestration/db/__init__.py\", line 159, in func_with_rollback\n    return func(*args, **kwargs)\n", "  File \"/usr/local/lib/python3.10/site-packages/mage_ai/orchestration/pipeline_scheduler_original.py\", line 333, in schedule\n    self.__schedule_blocks(block_runs)\n", "  File \"/usr/local/lib/python3.10/site-packages/mage_ai/orchestration/pipeline_scheduler_original.py\", line 640, in __schedule_blocks\n    job_manager.add_job(\n", "  File \"/usr/local/lib/python3.10/site-packages/mage_ai/orchestration/job_manager.py\", line 20, in add_job\n    self.queue.enqueue(job_id, target, *args, **kwargs)\n", "  File \"/usr/local/lib/python3.10/site-packages/mage_ai/orchestration/queue/process_queue.py\", line 122, in enqueue\n    self.start_worker_pool()\n", "  File \"/usr/local/lib/python3.10/site-packages/mage_ai/orchestration/queue/process_queue.py\", line 199, in start_worker_pool\n    self.worker_pool_proc.start()\n", "  File \"/usr/local/lib/python3.10/multiprocessing/process.py\", line 121, in start\n    self._popen = self._Popen(self)\n", "  File \"/usr/local/lib/python3.10/multiprocessing/context.py\", line 224, in _Popen\n    return _default_context.get_context().Process._Popen(process_obj)\n", "  File \"/usr/local/lib/python3.10/multiprocessing/context.py\", line 281, in _Popen\n    return Popen(process_obj)\n", "  File \"/usr/local/lib/python3.10/multiprocessing/popen_fork.py\", line 19, in __init__\n    self._launch(process_obj)\n", "  File \"/usr/local/lib/python3.10/multiprocessing/popen_fork.py\", line 71, in _launch\n    code = process_obj._bootstrap(parent_sentinel=child_r)\n", "  File \"/usr/local/lib/python3.10/multiprocessing/process.py\", line 314, in _bootstrap\n    self.run()\n", "  File \"/usr/local/lib/python3.10/multiprocessing/process.py\", line 108, in run\n    self._target(*self._args, **self._kwargs)\n", "  File \"/usr/local/lib/python3.10/site-packages/mage_ai/orchestration/queue/process_queue.py\", line 353, in poll_job_and_execute\n    worker.start()\n", "  File \"/usr/local/lib/python3.10/multiprocessing/process.py\", line 121, in start\n    self._popen = self._Popen(self)\n", "  File \"/usr/local/lib/python3.10/multiprocessing/context.py\", line 224, in _Popen\n    return _default_context.get_context().Process._Popen(process_obj)\n", "  File \"/usr/local/lib/python3.10/multiprocessing/context.py\", line 281, in _Popen\n    return Popen(process_obj)\n", "  File \"/usr/local/lib/python3.10/multiprocessing/popen_fork.py\", line 19, in __init__\n    self._launch(process_obj)\n", "  File \"/usr/local/lib/python3.10/multiprocessing/popen_fork.py\", line 71, in _launch\n    code = process_obj._bootstrap(parent_sentinel=child_r)\n", "  File \"/usr/local/lib/python3.10/multiprocessing/process.py\", line 314, in _bootstrap\n    self.run()\n", "  File \"/usr/local/lib/python3.10/site-packages/newrelic/api/background_task.py\", line 117, in wrapper\n    return wrapped(*args, **kwargs)\n", "  File \"/usr/local/lib/python3.10/site-packages/mage_ai/orchestration/queue/process_queue.py\", line 317, in run\n    start_session_and_run(args[1], *args[2], **args[3])\n", "  File \"/usr/local/lib/python3.10/site-packages/mage_ai/orchestration/db/process.py\", line 15, in start_session_and_run\n    results = target(*args)\n", "  File \"/usr/local/lib/python3.10/site-packages/mage_ai/orchestration/pipeline_scheduler_original.py\", line 1235, in run_block\n    return ExecutorFactory.get_block_executor(\n", "  File \"/usr/local/lib/python3.10/site-packages/mage_ai/data_preparation/executors/block_executor.py\", line 682, in execute\n    on_failure(\n", "  File \"/usr/local/lib/python3.10/site-packages/mage_ai/orchestration/db/__init__.py\", line 159, in func_with_rollback\n    return func(*args, **kwargs)\n", "  File \"/usr/local/lib/python3.10/site-packages/mage_ai/orchestration/pipeline_scheduler_original.py\", line 464, in on_block_failure\n    self.logger.exception(\n", "  File \"/usr/local/lib/python3.10/site-packages/mage_ai/data_preparation/logging/logger.py\", line 30, in exception\n    self.__send_message('exception', message, **kwargs)\n", "  File \"/usr/local/lib/python3.10/site-packages/mage_ai/data_preparation/logging/logger.py\", line 65, in __send_message\n    data['error_stack'] = traceback.format_stack()\n"], "error_stacktrace": "tuple index out of range"}
Traceback (most recent call last):
  File "/usr/local/lib/python3.10/site-packages/mage_ai/data_preparation/executors/block_executor.py", line 647, in execute
    result = __execute_with_retry()
  File "/usr/local/lib/python3.10/site-packages/mage_ai/shared/retry.py", line 54, in retry_func
    raise e
  File "/usr/local/lib/python3.10/site-packages/mage_ai/shared/retry.py", line 38, in retry_func
    return func(*args, **kwargs)
  File "/usr/local/lib/python3.10/site-packages/mage_ai/data_preparation/executors/block_executor.py", line 621, in __execute_with_retry
    return self._execute(
  File "/usr/local/lib/python3.10/site-packages/mage_ai/data_preparation/executors/block_executor.py", line 1154, in _execute
    result = self.block.execute_sync(
  File "/usr/local/lib/python3.10/site-packages/mage_ai/data_preparation/models/block/__init__.py", line 1691, in execute_sync
    return __execute()
  File "/usr/local/lib/python3.10/site-packages/mage_ai/data_preparation/models/block/__init__.py", line 1668, in __execute
    raise err
  File "/usr/local/lib/python3.10/site-packages/mage_ai/data_preparation/models/block/__init__.py", line 1570, in __execute
    output = self.execute_block(
  File "/usr/local/lib/python3.10/site-packages/mage_ai/data_preparation/models/block/__init__.py", line 1910, in execute_block
    outputs = self._execute_block(
  File "/usr/local/lib/python3.10/site-packages/mage_ai/data_preparation/models/block/__init__.py", line 2073, in _execute_block
    outputs = self.execute_block_function(
  File "/usr/local/lib/python3.10/site-packages/mage_ai/data_preparation/models/block/__init__.py", line 2169, in execute_block_function
    output = block_function_updated(*input_vars, **global_vars)
  File "<string>", line 122, in export_invoices_to_postgres
  File "/usr/local/lib/python3.10/site-packages/psycopg2/extras.py", line 1267, in execute_values
    parts.append(cur.mogrify(template, args))
IndexError: tuple index out of range
2025-09-13T00:00:57 {"cpu": 0.158203125, "cpu_total": 20, "cpu_usage": 0.00791015625, "memory": 2072.0, "memory_total": 9804.0, "memory_usage": 0.21134230926152592, "pipeline_run_id": 21, "pipeline_schedule_id": 2, "pipeline_uuid": "qb_invoices_bacfill", "hostname": "370646b43903", "level": "INFO", "message": "Pipeline qb_invoices_bacfill for run 21 in schedule 2 is alive.", "timestamp": 1757721657.008293, "uuid": "0c23c145ed9145ed95d49ca29392c3d4"}
