2025-09-12T23:08:39 {"cpu": 0.23974609375, "cpu_total": 20, "cpu_usage": 0.0119873046875, "memory": 2054.0, "memory_total": 9804.0, "memory_usage": 0.2095063239494084, "pipeline_run_id": 7, "pipeline_schedule_id": 2, "pipeline_uuid": "qb_invoices_bacfill", "hostname": "370646b43903", "level": "INFO", "message": "Pipeline qb_invoices_bacfill for run 7 in schedule 2 is alive.", "timestamp": 1757718519.720392, "uuid": "7bf1e832a4634dd38693fdd022969069"}
2025-09-12T23:08:40 {"block_run_id": 13, "block_uuid": "qb_invoices_loader", "pipeline_run_id": 7, "pipeline_schedule_id": 2, "pipeline_uuid": "qb_invoices_bacfill", "hostname": "370646b43903", "level": "INFO", "message": "Execute PipelineRun 7, BlockRun 13: pipeline qb_invoices_bacfill block qb_invoices_loader", "timestamp": 1757718520.065643, "uuid": "d1183b0a049a4db791b6c0e775045814"}
2025-09-12T23:08:40 {"cpu": 0.23974609375, "cpu_total": 20, "cpu_usage": 0.0119873046875, "memory": 2082.0, "memory_total": 9804.0, "memory_usage": 0.21236230110159118, "pipeline_run_id": 7, "pipeline_schedule_id": 2, "pipeline_uuid": "qb_invoices_bacfill", "hostname": "370646b43903", "level": "INFO", "message": "Pipeline qb_invoices_bacfill for run 7 in schedule 2 is alive.", "timestamp": 1757718520.222567, "uuid": "200698abce5c44ae921ddf498e237003"}
2025-09-12T23:08:42 {"block_run_id": 13, "block_uuid": "qb_invoices_loader", "pipeline_run_id": 7, "pipeline_schedule_id": 2, "pipeline_uuid": "qb_invoices_bacfill", "hostname": "370646b43903", "level": "EXCEPTION", "message": "BlockRun 13 (block_uuid: qb_invoices_loader) failed.", "timestamp": 1757718522.58042, "uuid": "5beb97b479044ff08233e13326b54962", "error": "Traceback (most recent call last):\n  File \"<string>\", line 77, in refresh_access_token\n  File \"/usr/local/lib/python3.10/site-packages/requests/models.py\", line 1021, in raise_for_status\n    raise HTTPError(http_error_msg, response=self)\nrequests.exceptions.HTTPError: 400 Client Error: Bad Request for url: https://oauth.platform.intuit.com/oauth2/v1/tokens/bearer\n\nThe above exception was the direct cause of the following exception:\n\nTraceback (most recent call last):\n  File \"/usr/local/lib/python3.10/site-packages/mage_ai/data_preparation/executors/block_executor.py\", line 647, in execute\n    result = __execute_with_retry()\n  File \"/usr/local/lib/python3.10/site-packages/mage_ai/shared/retry.py\", line 54, in retry_func\n    raise e\n  File \"/usr/local/lib/python3.10/site-packages/mage_ai/shared/retry.py\", line 38, in retry_func\n    return func(*args, **kwargs)\n  File \"/usr/local/lib/python3.10/site-packages/mage_ai/data_preparation/executors/block_executor.py\", line 621, in __execute_with_retry\n    return self._execute(\n  File \"/usr/local/lib/python3.10/site-packages/mage_ai/data_preparation/executors/block_executor.py\", line 1154, in _execute\n    result = self.block.execute_sync(\n  File \"/usr/local/lib/python3.10/site-packages/mage_ai/data_preparation/models/block/__init__.py\", line 1691, in execute_sync\n    return __execute()\n  File \"/usr/local/lib/python3.10/site-packages/mage_ai/data_preparation/models/block/__init__.py\", line 1668, in __execute\n    raise err\n  File \"/usr/local/lib/python3.10/site-packages/mage_ai/data_preparation/models/block/__init__.py\", line 1570, in __execute\n    output = self.execute_block(\n  File \"/usr/local/lib/python3.10/site-packages/mage_ai/data_preparation/models/block/__init__.py\", line 1910, in execute_block\n    outputs = self._execute_block(\n  File \"/usr/local/lib/python3.10/site-packages/mage_ai/data_preparation/models/block/__init__.py\", line 2073, in _execute_block\n    outputs = self.execute_block_function(\n  File \"/usr/local/lib/python3.10/site-packages/mage_ai/data_preparation/models/block/__init__.py\", line 2169, in execute_block_function\n    output = block_function_updated(*input_vars, **global_vars)\n  File \"<string>\", line 212, in load_data\n  File \"<string>\", line 79, in refresh_access_token\nRuntimeError: Error al refrescar token: 400 {\"error\":\"invalid_grant\"}\n", "error_stack": ["  File \"/usr/local/bin/mage\", line 8, in <module>\n    sys.exit(app())\n", "  File \"/usr/local/lib/python3.10/site-packages/typer/main.py\", line 311, in __call__\n    return get_command(self)(*args, **kwargs)\n", "  File \"/usr/local/lib/python3.10/site-packages/click/core.py\", line 1442, in __call__\n    return self.main(*args, **kwargs)\n", "  File \"/usr/local/lib/python3.10/site-packages/typer/core.py\", line 778, in main\n    return _main(\n", "  File \"/usr/local/lib/python3.10/site-packages/typer/core.py\", line 216, in _main\n    rv = self.invoke(ctx)\n", "  File \"/usr/local/lib/python3.10/site-packages/click/core.py\", line 1830, in invoke\n    return _process_result(sub_ctx.command.invoke(sub_ctx))\n", "  File \"/usr/local/lib/python3.10/site-packages/click/core.py\", line 1226, in invoke\n    return ctx.invoke(self.callback, **ctx.params)\n", "  File \"/usr/local/lib/python3.10/site-packages/click/core.py\", line 794, in invoke\n    return callback(*args, **kwargs)\n", "  File \"/usr/local/lib/python3.10/site-packages/typer/main.py\", line 683, in wrapper\n    return callback(**use_params)  # type: ignore\n", "  File \"/usr/local/lib/python3.10/site-packages/mage_ai/cli/main.py\", line 147, in start\n    start_server(\n", "  File \"/usr/local/lib/python3.10/site-packages/mage_ai/server/server.py\", line 809, in start_server\n    scheduler_manager.start_scheduler()\n", "  File \"/usr/local/lib/python3.10/site-packages/mage_ai/server/scheduler_manager.py\", line 108, in start_scheduler\n    proc.start()\n", "  File \"/usr/local/lib/python3.10/multiprocessing/process.py\", line 121, in start\n    self._popen = self._Popen(self)\n", "  File \"/usr/local/lib/python3.10/multiprocessing/context.py\", line 224, in _Popen\n    return _default_context.get_context().Process._Popen(process_obj)\n", "  File \"/usr/local/lib/python3.10/multiprocessing/context.py\", line 281, in _Popen\n    return Popen(process_obj)\n", "  File \"/usr/local/lib/python3.10/multiprocessing/popen_fork.py\", line 19, in __init__\n    self._launch(process_obj)\n", "  File \"/usr/local/lib/python3.10/multiprocessing/popen_fork.py\", line 71, in _launch\n    code = process_obj._bootstrap(parent_sentinel=child_r)\n", "  File \"/usr/local/lib/python3.10/multiprocessing/process.py\", line 314, in _bootstrap\n    self.run()\n", "  File \"/usr/local/lib/python3.10/multiprocessing/process.py\", line 108, in run\n    self._target(*self._args, **self._kwargs)\n", "  File \"/usr/local/lib/python3.10/site-packages/mage_ai/orchestration/db/process.py\", line 15, in start_session_and_run\n    results = target(*args)\n", "  File \"/usr/local/lib/python3.10/site-packages/mage_ai/server/scheduler_manager.py\", line 60, in run_scheduler\n    LoopTimeTrigger().start()\n", "  File \"/usr/local/lib/python3.10/site-packages/mage_ai/orchestration/triggers/loop_time_trigger.py\", line 14, in start\n    self.run()\n", "  File \"/usr/local/lib/python3.10/site-packages/mage_ai/orchestration/triggers/time_trigger.py\", line 11, in run\n    schedule_all()\n", "  File \"/usr/local/lib/python3.10/site-packages/mage_ai/orchestration/pipeline_scheduler_original.py\", line 1702, in schedule_all\n    PipelineScheduler(r).start()\n", "  File \"/usr/local/lib/python3.10/site-packages/mage_ai/orchestration/db/__init__.py\", line 159, in func_with_rollback\n    return func(*args, **kwargs)\n", "  File \"/usr/local/lib/python3.10/site-packages/mage_ai/orchestration/pipeline_scheduler_original.py\", line 197, in start\n    self.schedule()\n", "  File \"/usr/local/lib/python3.10/site-packages/mage_ai/orchestration/db/__init__.py\", line 159, in func_with_rollback\n    return func(*args, **kwargs)\n", "  File \"/usr/local/lib/python3.10/site-packages/mage_ai/orchestration/pipeline_scheduler_original.py\", line 333, in schedule\n    self.__schedule_blocks(block_runs)\n", "  File \"/usr/local/lib/python3.10/site-packages/mage_ai/orchestration/pipeline_scheduler_original.py\", line 640, in __schedule_blocks\n    job_manager.add_job(\n", "  File \"/usr/local/lib/python3.10/site-packages/mage_ai/orchestration/job_manager.py\", line 20, in add_job\n    self.queue.enqueue(job_id, target, *args, **kwargs)\n", "  File \"/usr/local/lib/python3.10/site-packages/mage_ai/orchestration/queue/process_queue.py\", line 122, in enqueue\n    self.start_worker_pool()\n", "  File \"/usr/local/lib/python3.10/site-packages/mage_ai/orchestration/queue/process_queue.py\", line 199, in start_worker_pool\n    self.worker_pool_proc.start()\n", "  File \"/usr/local/lib/python3.10/multiprocessing/process.py\", line 121, in start\n    self._popen = self._Popen(self)\n", "  File \"/usr/local/lib/python3.10/multiprocessing/context.py\", line 224, in _Popen\n    return _default_context.get_context().Process._Popen(process_obj)\n", "  File \"/usr/local/lib/python3.10/multiprocessing/context.py\", line 281, in _Popen\n    return Popen(process_obj)\n", "  File \"/usr/local/lib/python3.10/multiprocessing/popen_fork.py\", line 19, in __init__\n    self._launch(process_obj)\n", "  File \"/usr/local/lib/python3.10/multiprocessing/popen_fork.py\", line 71, in _launch\n    code = process_obj._bootstrap(parent_sentinel=child_r)\n", "  File \"/usr/local/lib/python3.10/multiprocessing/process.py\", line 314, in _bootstrap\n    self.run()\n", "  File \"/usr/local/lib/python3.10/multiprocessing/process.py\", line 108, in run\n    self._target(*self._args, **self._kwargs)\n", "  File \"/usr/local/lib/python3.10/site-packages/mage_ai/orchestration/queue/process_queue.py\", line 353, in poll_job_and_execute\n    worker.start()\n", "  File \"/usr/local/lib/python3.10/multiprocessing/process.py\", line 121, in start\n    self._popen = self._Popen(self)\n", "  File \"/usr/local/lib/python3.10/multiprocessing/context.py\", line 224, in _Popen\n    return _default_context.get_context().Process._Popen(process_obj)\n", "  File \"/usr/local/lib/python3.10/multiprocessing/context.py\", line 281, in _Popen\n    return Popen(process_obj)\n", "  File \"/usr/local/lib/python3.10/multiprocessing/popen_fork.py\", line 19, in __init__\n    self._launch(process_obj)\n", "  File \"/usr/local/lib/python3.10/multiprocessing/popen_fork.py\", line 71, in _launch\n    code = process_obj._bootstrap(parent_sentinel=child_r)\n", "  File \"/usr/local/lib/python3.10/multiprocessing/process.py\", line 314, in _bootstrap\n    self.run()\n", "  File \"/usr/local/lib/python3.10/site-packages/newrelic/api/background_task.py\", line 117, in wrapper\n    return wrapped(*args, **kwargs)\n", "  File \"/usr/local/lib/python3.10/site-packages/mage_ai/orchestration/queue/process_queue.py\", line 317, in run\n    start_session_and_run(args[1], *args[2], **args[3])\n", "  File \"/usr/local/lib/python3.10/site-packages/mage_ai/orchestration/db/process.py\", line 15, in start_session_and_run\n    results = target(*args)\n", "  File \"/usr/local/lib/python3.10/site-packages/mage_ai/orchestration/pipeline_scheduler_original.py\", line 1235, in run_block\n    return ExecutorFactory.get_block_executor(\n", "  File \"/usr/local/lib/python3.10/site-packages/mage_ai/data_preparation/executors/block_executor.py\", line 682, in execute\n    on_failure(\n", "  File \"/usr/local/lib/python3.10/site-packages/mage_ai/orchestration/db/__init__.py\", line 159, in func_with_rollback\n    return func(*args, **kwargs)\n", "  File \"/usr/local/lib/python3.10/site-packages/mage_ai/orchestration/pipeline_scheduler_original.py\", line 464, in on_block_failure\n    self.logger.exception(\n", "  File \"/usr/local/lib/python3.10/site-packages/mage_ai/data_preparation/logging/logger.py\", line 30, in exception\n    self.__send_message('exception', message, **kwargs)\n", "  File \"/usr/local/lib/python3.10/site-packages/mage_ai/data_preparation/logging/logger.py\", line 65, in __send_message\n    data['error_stack'] = traceback.format_stack()\n"], "error_stacktrace": "Error al refrescar token: 400 {\"error\":\"invalid_grant\"}"}
Traceback (most recent call last):
  File "<string>", line 77, in refresh_access_token
  File "/usr/local/lib/python3.10/site-packages/requests/models.py", line 1021, in raise_for_status
    raise HTTPError(http_error_msg, response=self)
requests.exceptions.HTTPError: 400 Client Error: Bad Request for url: https://oauth.platform.intuit.com/oauth2/v1/tokens/bearer

The above exception was the direct cause of the following exception:

Traceback (most recent call last):
  File "/usr/local/lib/python3.10/site-packages/mage_ai/data_preparation/executors/block_executor.py", line 647, in execute
    result = __execute_with_retry()
  File "/usr/local/lib/python3.10/site-packages/mage_ai/shared/retry.py", line 54, in retry_func
    raise e
  File "/usr/local/lib/python3.10/site-packages/mage_ai/shared/retry.py", line 38, in retry_func
    return func(*args, **kwargs)
  File "/usr/local/lib/python3.10/site-packages/mage_ai/data_preparation/executors/block_executor.py", line 621, in __execute_with_retry
    return self._execute(
  File "/usr/local/lib/python3.10/site-packages/mage_ai/data_preparation/executors/block_executor.py", line 1154, in _execute
    result = self.block.execute_sync(
  File "/usr/local/lib/python3.10/site-packages/mage_ai/data_preparation/models/block/__init__.py", line 1691, in execute_sync
    return __execute()
  File "/usr/local/lib/python3.10/site-packages/mage_ai/data_preparation/models/block/__init__.py", line 1668, in __execute
    raise err
  File "/usr/local/lib/python3.10/site-packages/mage_ai/data_preparation/models/block/__init__.py", line 1570, in __execute
    output = self.execute_block(
  File "/usr/local/lib/python3.10/site-packages/mage_ai/data_preparation/models/block/__init__.py", line 1910, in execute_block
    outputs = self._execute_block(
  File "/usr/local/lib/python3.10/site-packages/mage_ai/data_preparation/models/block/__init__.py", line 2073, in _execute_block
    outputs = self.execute_block_function(
  File "/usr/local/lib/python3.10/site-packages/mage_ai/data_preparation/models/block/__init__.py", line 2169, in execute_block_function
    output = block_function_updated(*input_vars, **global_vars)
  File "<string>", line 212, in load_data
  File "<string>", line 79, in refresh_access_token
RuntimeError: Error al refrescar token: 400 {"error":"invalid_grant"}
2025-09-12T23:08:49 {"cpu": 0.24267578125, "cpu_total": 20, "cpu_usage": 0.0121337890625, "memory": 2017.0, "memory_total": 9804.0, "memory_usage": 0.20573235414116686, "pipeline_run_id": 7, "pipeline_schedule_id": 2, "pipeline_uuid": "qb_invoices_bacfill", "hostname": "370646b43903", "level": "INFO", "message": "Pipeline qb_invoices_bacfill for run 7 in schedule 2 is alive.", "timestamp": 1757718529.993146, "uuid": "5440af7eee664aa9867137e673c33b3a"}
2025-09-12T23:11:30 {"cpu": 0.3076171875, "cpu_total": 20, "cpu_usage": 0.015380859375, "memory": 2076.0, "memory_total": 9804.0, "memory_usage": 0.211750305997552, "pipeline_run_id": 10, "pipeline_schedule_id": 2, "pipeline_uuid": "qb_invoices_bacfill", "hostname": "370646b43903", "level": "INFO", "message": "Pipeline qb_invoices_bacfill for run 10 in schedule 2 is alive.", "timestamp": 1757718690.121677, "uuid": "e3d07210d9a74b4e87bdbf2b6e730486"}
2025-09-12T23:11:30 {"cpu": 0.3076171875, "cpu_total": 20, "cpu_usage": 0.015380859375, "memory": 2089.0, "memory_total": 9804.0, "memory_usage": 0.21307629538963688, "pipeline_run_id": 10, "pipeline_schedule_id": 2, "pipeline_uuid": "qb_invoices_bacfill", "hostname": "370646b43903", "level": "INFO", "message": "Pipeline qb_invoices_bacfill for run 10 in schedule 2 is alive.", "timestamp": 1757718690.579077, "uuid": "a16ebf86e5a74897871fc9b3e170a1dd"}
2025-09-12T23:11:30 {"block_run_id": 19, "block_uuid": "qb_invoices_loader", "pipeline_run_id": 10, "pipeline_schedule_id": 2, "pipeline_uuid": "qb_invoices_bacfill", "hostname": "370646b43903", "level": "INFO", "message": "Execute PipelineRun 10, BlockRun 19: pipeline qb_invoices_bacfill block qb_invoices_loader", "timestamp": 1757718690.675819, "uuid": "3d016d76e7104182b231828eb81cda97"}
2025-09-12T23:11:41 {"cpu": 0.3095703125, "cpu_total": 20, "cpu_usage": 0.015478515625, "memory": 2080.0, "memory_total": 9804.0, "memory_usage": 0.21215830273357814, "pipeline_run_id": 10, "pipeline_schedule_id": 2, "pipeline_uuid": "qb_invoices_bacfill", "hostname": "370646b43903", "level": "INFO", "message": "Pipeline qb_invoices_bacfill for run 10 in schedule 2 is alive.", "timestamp": 1757718701.075029, "uuid": "f0abcb0b4bed4f61bdc361caf7f3c2b1"}
2025-09-12T23:11:46 {"block_run_id": 19, "block_uuid": "qb_invoices_loader", "pipeline_run_id": 10, "pipeline_schedule_id": 2, "pipeline_uuid": "qb_invoices_bacfill", "hostname": "370646b43903", "level": "INFO", "message": "BlockRun 19 (block_uuid: qb_invoices_loader) completes.", "timestamp": 1757718706.106641, "uuid": "5a22ff56de0941bb8b86522de46f745b"}
2025-09-12T23:11:50 {"cpu": 0.3076171875, "cpu_total": 20, "cpu_usage": 0.015380859375, "memory": 2082.0, "memory_total": 9804.0, "memory_usage": 0.21236230110159118, "pipeline_run_id": 10, "pipeline_schedule_id": 2, "pipeline_uuid": "qb_invoices_bacfill", "hostname": "370646b43903", "level": "INFO", "message": "Pipeline qb_invoices_bacfill for run 10 in schedule 2 is alive.", "timestamp": 1757718710.021222, "uuid": "3b86cc8d2be54a9d8e9f1275f479a645"}
2025-09-12T23:11:50 {"block_run_id": 20, "block_uuid": "qb_invoices_exporter", "pipeline_run_id": 10, "pipeline_schedule_id": 2, "pipeline_uuid": "qb_invoices_bacfill", "hostname": "370646b43903", "level": "INFO", "message": "Execute PipelineRun 10, BlockRun 20: pipeline qb_invoices_bacfill block qb_invoices_exporter", "timestamp": 1757718710.839995, "uuid": "3e2a687916b14a09a156f7591df9c7a5"}
2025-09-12T23:11:51 {"block_run_id": 20, "block_uuid": "qb_invoices_exporter", "pipeline_run_id": 10, "pipeline_schedule_id": 2, "pipeline_uuid": "qb_invoices_bacfill", "hostname": "370646b43903", "level": "EXCEPTION", "message": "BlockRun 20 (block_uuid: qb_invoices_exporter) failed.", "timestamp": 1757718711.335307, "uuid": "03d36f207d3b44a2a2848ec4a25b2c18", "error": "Traceback (most recent call last):\n  File \"/usr/local/lib/python3.10/site-packages/mage_ai/data_preparation/executors/block_executor.py\", line 647, in execute\n    result = __execute_with_retry()\n  File \"/usr/local/lib/python3.10/site-packages/mage_ai/shared/retry.py\", line 54, in retry_func\n    raise e\n  File \"/usr/local/lib/python3.10/site-packages/mage_ai/shared/retry.py\", line 38, in retry_func\n    return func(*args, **kwargs)\n  File \"/usr/local/lib/python3.10/site-packages/mage_ai/data_preparation/executors/block_executor.py\", line 621, in __execute_with_retry\n    return self._execute(\n  File \"/usr/local/lib/python3.10/site-packages/mage_ai/data_preparation/executors/block_executor.py\", line 1154, in _execute\n    result = self.block.execute_sync(\n  File \"/usr/local/lib/python3.10/site-packages/mage_ai/data_preparation/models/block/__init__.py\", line 1691, in execute_sync\n    return __execute()\n  File \"/usr/local/lib/python3.10/site-packages/mage_ai/data_preparation/models/block/__init__.py\", line 1668, in __execute\n    raise err\n  File \"/usr/local/lib/python3.10/site-packages/mage_ai/data_preparation/models/block/__init__.py\", line 1570, in __execute\n    output = self.execute_block(\n  File \"/usr/local/lib/python3.10/site-packages/mage_ai/data_preparation/models/block/__init__.py\", line 1910, in execute_block\n    outputs = self._execute_block(\n  File \"/usr/local/lib/python3.10/site-packages/mage_ai/data_preparation/models/block/__init__.py\", line 2041, in _execute_block\n    exec(self.content, results)\n  File \"<string>\", line 112\n    \"source\": \"mage\",\n            ^\nSyntaxError: invalid syntax\n", "error_stack": ["  File \"/usr/local/bin/mage\", line 8, in <module>\n    sys.exit(app())\n", "  File \"/usr/local/lib/python3.10/site-packages/typer/main.py\", line 311, in __call__\n    return get_command(self)(*args, **kwargs)\n", "  File \"/usr/local/lib/python3.10/site-packages/click/core.py\", line 1442, in __call__\n    return self.main(*args, **kwargs)\n", "  File \"/usr/local/lib/python3.10/site-packages/typer/core.py\", line 778, in main\n    return _main(\n", "  File \"/usr/local/lib/python3.10/site-packages/typer/core.py\", line 216, in _main\n    rv = self.invoke(ctx)\n", "  File \"/usr/local/lib/python3.10/site-packages/click/core.py\", line 1830, in invoke\n    return _process_result(sub_ctx.command.invoke(sub_ctx))\n", "  File \"/usr/local/lib/python3.10/site-packages/click/core.py\", line 1226, in invoke\n    return ctx.invoke(self.callback, **ctx.params)\n", "  File \"/usr/local/lib/python3.10/site-packages/click/core.py\", line 794, in invoke\n    return callback(*args, **kwargs)\n", "  File \"/usr/local/lib/python3.10/site-packages/typer/main.py\", line 683, in wrapper\n    return callback(**use_params)  # type: ignore\n", "  File \"/usr/local/lib/python3.10/site-packages/mage_ai/cli/main.py\", line 147, in start\n    start_server(\n", "  File \"/usr/local/lib/python3.10/site-packages/mage_ai/server/server.py\", line 809, in start_server\n    scheduler_manager.start_scheduler()\n", "  File \"/usr/local/lib/python3.10/site-packages/mage_ai/server/scheduler_manager.py\", line 108, in start_scheduler\n    proc.start()\n", "  File \"/usr/local/lib/python3.10/multiprocessing/process.py\", line 121, in start\n    self._popen = self._Popen(self)\n", "  File \"/usr/local/lib/python3.10/multiprocessing/context.py\", line 224, in _Popen\n    return _default_context.get_context().Process._Popen(process_obj)\n", "  File \"/usr/local/lib/python3.10/multiprocessing/context.py\", line 281, in _Popen\n    return Popen(process_obj)\n", "  File \"/usr/local/lib/python3.10/multiprocessing/popen_fork.py\", line 19, in __init__\n    self._launch(process_obj)\n", "  File \"/usr/local/lib/python3.10/multiprocessing/popen_fork.py\", line 71, in _launch\n    code = process_obj._bootstrap(parent_sentinel=child_r)\n", "  File \"/usr/local/lib/python3.10/multiprocessing/process.py\", line 314, in _bootstrap\n    self.run()\n", "  File \"/usr/local/lib/python3.10/multiprocessing/process.py\", line 108, in run\n    self._target(*self._args, **self._kwargs)\n", "  File \"/usr/local/lib/python3.10/site-packages/mage_ai/orchestration/db/process.py\", line 15, in start_session_and_run\n    results = target(*args)\n", "  File \"/usr/local/lib/python3.10/site-packages/mage_ai/server/scheduler_manager.py\", line 60, in run_scheduler\n    LoopTimeTrigger().start()\n", "  File \"/usr/local/lib/python3.10/site-packages/mage_ai/orchestration/triggers/loop_time_trigger.py\", line 14, in start\n    self.run()\n", "  File \"/usr/local/lib/python3.10/site-packages/mage_ai/orchestration/triggers/time_trigger.py\", line 11, in run\n    schedule_all()\n", "  File \"/usr/local/lib/python3.10/site-packages/mage_ai/orchestration/pipeline_scheduler_original.py\", line 1702, in schedule_all\n    PipelineScheduler(r).start()\n", "  File \"/usr/local/lib/python3.10/site-packages/mage_ai/orchestration/db/__init__.py\", line 159, in func_with_rollback\n    return func(*args, **kwargs)\n", "  File \"/usr/local/lib/python3.10/site-packages/mage_ai/orchestration/pipeline_scheduler_original.py\", line 197, in start\n    self.schedule()\n", "  File \"/usr/local/lib/python3.10/site-packages/mage_ai/orchestration/db/__init__.py\", line 159, in func_with_rollback\n    return func(*args, **kwargs)\n", "  File \"/usr/local/lib/python3.10/site-packages/mage_ai/orchestration/pipeline_scheduler_original.py\", line 333, in schedule\n    self.__schedule_blocks(block_runs)\n", "  File \"/usr/local/lib/python3.10/site-packages/mage_ai/orchestration/pipeline_scheduler_original.py\", line 640, in __schedule_blocks\n    job_manager.add_job(\n", "  File \"/usr/local/lib/python3.10/site-packages/mage_ai/orchestration/job_manager.py\", line 20, in add_job\n    self.queue.enqueue(job_id, target, *args, **kwargs)\n", "  File \"/usr/local/lib/python3.10/site-packages/mage_ai/orchestration/queue/process_queue.py\", line 122, in enqueue\n    self.start_worker_pool()\n", "  File \"/usr/local/lib/python3.10/site-packages/mage_ai/orchestration/queue/process_queue.py\", line 199, in start_worker_pool\n    self.worker_pool_proc.start()\n", "  File \"/usr/local/lib/python3.10/multiprocessing/process.py\", line 121, in start\n    self._popen = self._Popen(self)\n", "  File \"/usr/local/lib/python3.10/multiprocessing/context.py\", line 224, in _Popen\n    return _default_context.get_context().Process._Popen(process_obj)\n", "  File \"/usr/local/lib/python3.10/multiprocessing/context.py\", line 281, in _Popen\n    return Popen(process_obj)\n", "  File \"/usr/local/lib/python3.10/multiprocessing/popen_fork.py\", line 19, in __init__\n    self._launch(process_obj)\n", "  File \"/usr/local/lib/python3.10/multiprocessing/popen_fork.py\", line 71, in _launch\n    code = process_obj._bootstrap(parent_sentinel=child_r)\n", "  File \"/usr/local/lib/python3.10/multiprocessing/process.py\", line 314, in _bootstrap\n    self.run()\n", "  File \"/usr/local/lib/python3.10/multiprocessing/process.py\", line 108, in run\n    self._target(*self._args, **self._kwargs)\n", "  File \"/usr/local/lib/python3.10/site-packages/mage_ai/orchestration/queue/process_queue.py\", line 353, in poll_job_and_execute\n    worker.start()\n", "  File \"/usr/local/lib/python3.10/multiprocessing/process.py\", line 121, in start\n    self._popen = self._Popen(self)\n", "  File \"/usr/local/lib/python3.10/multiprocessing/context.py\", line 224, in _Popen\n    return _default_context.get_context().Process._Popen(process_obj)\n", "  File \"/usr/local/lib/python3.10/multiprocessing/context.py\", line 281, in _Popen\n    return Popen(process_obj)\n", "  File \"/usr/local/lib/python3.10/multiprocessing/popen_fork.py\", line 19, in __init__\n    self._launch(process_obj)\n", "  File \"/usr/local/lib/python3.10/multiprocessing/popen_fork.py\", line 71, in _launch\n    code = process_obj._bootstrap(parent_sentinel=child_r)\n", "  File \"/usr/local/lib/python3.10/multiprocessing/process.py\", line 314, in _bootstrap\n    self.run()\n", "  File \"/usr/local/lib/python3.10/site-packages/newrelic/api/background_task.py\", line 117, in wrapper\n    return wrapped(*args, **kwargs)\n", "  File \"/usr/local/lib/python3.10/site-packages/mage_ai/orchestration/queue/process_queue.py\", line 317, in run\n    start_session_and_run(args[1], *args[2], **args[3])\n", "  File \"/usr/local/lib/python3.10/site-packages/mage_ai/orchestration/db/process.py\", line 15, in start_session_and_run\n    results = target(*args)\n", "  File \"/usr/local/lib/python3.10/site-packages/mage_ai/orchestration/pipeline_scheduler_original.py\", line 1235, in run_block\n    return ExecutorFactory.get_block_executor(\n", "  File \"/usr/local/lib/python3.10/site-packages/mage_ai/data_preparation/executors/block_executor.py\", line 682, in execute\n    on_failure(\n", "  File \"/usr/local/lib/python3.10/site-packages/mage_ai/orchestration/db/__init__.py\", line 159, in func_with_rollback\n    return func(*args, **kwargs)\n", "  File \"/usr/local/lib/python3.10/site-packages/mage_ai/orchestration/pipeline_scheduler_original.py\", line 464, in on_block_failure\n    self.logger.exception(\n", "  File \"/usr/local/lib/python3.10/site-packages/mage_ai/data_preparation/logging/logger.py\", line 30, in exception\n    self.__send_message('exception', message, **kwargs)\n", "  File \"/usr/local/lib/python3.10/site-packages/mage_ai/data_preparation/logging/logger.py\", line 65, in __send_message\n    data['error_stack'] = traceback.format_stack()\n"], "error_stacktrace": "invalid syntax (<string>, line 112)"}
Traceback (most recent call last):
  File "/usr/local/lib/python3.10/site-packages/mage_ai/data_preparation/executors/block_executor.py", line 647, in execute
    result = __execute_with_retry()
  File "/usr/local/lib/python3.10/site-packages/mage_ai/shared/retry.py", line 54, in retry_func
    raise e
  File "/usr/local/lib/python3.10/site-packages/mage_ai/shared/retry.py", line 38, in retry_func
    return func(*args, **kwargs)
  File "/usr/local/lib/python3.10/site-packages/mage_ai/data_preparation/executors/block_executor.py", line 621, in __execute_with_retry
    return self._execute(
  File "/usr/local/lib/python3.10/site-packages/mage_ai/data_preparation/executors/block_executor.py", line 1154, in _execute
    result = self.block.execute_sync(
  File "/usr/local/lib/python3.10/site-packages/mage_ai/data_preparation/models/block/__init__.py", line 1691, in execute_sync
    return __execute()
  File "/usr/local/lib/python3.10/site-packages/mage_ai/data_preparation/models/block/__init__.py", line 1668, in __execute
    raise err
  File "/usr/local/lib/python3.10/site-packages/mage_ai/data_preparation/models/block/__init__.py", line 1570, in __execute
    output = self.execute_block(
  File "/usr/local/lib/python3.10/site-packages/mage_ai/data_preparation/models/block/__init__.py", line 1910, in execute_block
    outputs = self._execute_block(
  File "/usr/local/lib/python3.10/site-packages/mage_ai/data_preparation/models/block/__init__.py", line 2041, in _execute_block
    exec(self.content, results)
  File "<string>", line 112
    "source": "mage",
            ^
SyntaxError: invalid syntax
2025-09-12T23:11:59 {"cpu": 0.31494140625, "cpu_total": 20, "cpu_usage": 0.0157470703125, "memory": 2080.0, "memory_total": 9804.0, "memory_usage": 0.21215830273357814, "pipeline_run_id": 10, "pipeline_schedule_id": 2, "pipeline_uuid": "qb_invoices_bacfill", "hostname": "370646b43903", "level": "INFO", "message": "Pipeline qb_invoices_bacfill for run 10 in schedule 2 is alive.", "timestamp": 1757718719.733705, "uuid": "5ee56da8a67a44138bdc526c3371bc3a"}
2025-09-12T23:14:21 {"cpu": 0.451171875, "cpu_total": 20, "cpu_usage": 0.02255859375, "memory": 2079.0, "memory_total": 9804.0, "memory_usage": 0.2120563035495716, "pipeline_run_id": 13, "pipeline_schedule_id": 2, "pipeline_uuid": "qb_invoices_bacfill", "hostname": "370646b43903", "level": "INFO", "message": "Pipeline qb_invoices_bacfill for run 13 in schedule 2 is alive.", "timestamp": 1757718861.452471, "uuid": "7271b70f161a4b99b565de4e1eda1271"}
2025-09-12T23:14:22 {"cpu": 0.451171875, "cpu_total": 20, "cpu_usage": 0.02255859375, "memory": 2120.0, "memory_total": 9804.0, "memory_usage": 0.21623827009383925, "pipeline_run_id": 13, "pipeline_schedule_id": 2, "pipeline_uuid": "qb_invoices_bacfill", "hostname": "370646b43903", "level": "INFO", "message": "Pipeline qb_invoices_bacfill for run 13 in schedule 2 is alive.", "timestamp": 1757718862.72157, "uuid": "0517a96a68484ef0a4d817f09b636642"}
2025-09-12T23:14:22 {"block_run_id": 25, "block_uuid": "qb_invoices_loader", "pipeline_run_id": 13, "pipeline_schedule_id": 2, "pipeline_uuid": "qb_invoices_bacfill", "hostname": "370646b43903", "level": "INFO", "message": "Execute PipelineRun 13, BlockRun 25: pipeline qb_invoices_bacfill block qb_invoices_loader", "timestamp": 1757718862.852975, "uuid": "b539ced3c2184fe189b6f74812416a36"}
2025-09-12T23:14:30 {"cpu": 0.4951171875, "cpu_total": 20, "cpu_usage": 0.024755859375, "memory": 2114.0, "memory_total": 9804.0, "memory_usage": 0.21562627498980008, "pipeline_run_id": 13, "pipeline_schedule_id": 2, "pipeline_uuid": "qb_invoices_bacfill", "hostname": "370646b43903", "level": "INFO", "message": "Pipeline qb_invoices_bacfill for run 13 in schedule 2 is alive.", "timestamp": 1757718870.466166, "uuid": "ec1af9bcf14946098496f875d9e9b5ef"}
2025-09-12T23:14:39 {"block_run_id": 25, "block_uuid": "qb_invoices_loader", "pipeline_run_id": 13, "pipeline_schedule_id": 2, "pipeline_uuid": "qb_invoices_bacfill", "hostname": "370646b43903", "level": "INFO", "message": "BlockRun 25 (block_uuid: qb_invoices_loader) completes.", "timestamp": 1757718879.31312, "uuid": "cdc30cbc3858479d9912785b65e96a51"}
2025-09-12T23:14:41 {"cpu": 0.51171875, "cpu_total": 20, "cpu_usage": 0.0255859375, "memory": 2023.0, "memory_total": 9804.0, "memory_usage": 0.20634434924520603, "pipeline_run_id": 13, "pipeline_schedule_id": 2, "pipeline_uuid": "qb_invoices_bacfill", "hostname": "370646b43903", "level": "INFO", "message": "Pipeline qb_invoices_bacfill for run 13 in schedule 2 is alive.", "timestamp": 1757718881.838807, "uuid": "5fc534962abd498ab2cd8e3ceb7f2a8b"}
2025-09-12T23:14:42 {"block_run_id": 26, "block_uuid": "qb_invoices_exporter", "pipeline_run_id": 13, "pipeline_schedule_id": 2, "pipeline_uuid": "qb_invoices_bacfill", "hostname": "370646b43903", "level": "INFO", "message": "Execute PipelineRun 13, BlockRun 26: pipeline qb_invoices_bacfill block qb_invoices_exporter", "timestamp": 1757718882.747097, "uuid": "e1da7be61bcd42a295bc4503df9139ae"}
2025-09-12T23:14:44 {"block_run_id": 26, "block_uuid": "qb_invoices_exporter", "pipeline_run_id": 13, "pipeline_schedule_id": 2, "pipeline_uuid": "qb_invoices_bacfill", "hostname": "370646b43903", "level": "INFO", "message": "BlockRun 26 (block_uuid: qb_invoices_exporter) completes.", "timestamp": 1757718884.398073, "uuid": "d58897cec49a48d0bf387a2cac89499c"}
2025-09-12T23:14:50 {"cpu": 0.53076171875, "cpu_total": 20, "cpu_usage": 0.0265380859375, "memory": 2017.0, "memory_total": 9804.0, "memory_usage": 0.20573235414116686, "pipeline_run_id": 13, "pipeline_schedule_id": 2, "pipeline_uuid": "qb_invoices_bacfill", "hostname": "370646b43903", "level": "INFO", "message": "Pipeline qb_invoices_bacfill for run 13 in schedule 2 is alive.", "timestamp": 1757718890.40115, "uuid": "a56caf5e1ccf42b5abb430fcea47c115"}
